try{
    console.log("Bussiness Logic")
    a = 10
    console.log(a)
}catch(e){
    console.log("Errors are encountered here", e)
}finally{
    console.log("Used for Closing the resources")
    console.log("Irresoective of error It will execute")
}